<?xml version="1.0"?>
<robot name="Robotarm">
  <material name="blue">
    <color rgba="0 0 0.8 1"/>
  </material>

  <link name="base_link">
    <visual>
      <origin xyz= "0 0 0.0962"/>
      <geometry>
        <box size="0.4572 0.34480000128 0.19240000128"/>
      </geometry>
      <material name="blue"/>
    </visual>
    <collision>
      <origin xyz= "0 0 0.0962"/>
      <geometry>
         <box size="0.4572 0.34480000128 0.19240000128"/>
      </geometry>
    </collision>
  </link>

  <link name="DOF1">
    <visual>
      <origin xyz= "0 0 0"/>
      <geometry>
        <cylinder length="0.05" radius="0.1"/>
      </geometry>
      <material name="blue"/>
    </visual>
     <collision>
      <origin xyz= "0 0 0"/>
      <geometry>
         <cylinder length="0.05" radius="0.1"/>
      </geometry>
    </collision>
  </link>

  <joint name="joint_to_DOF1" type="continuous">
    <parent link="base_link"/>
    <child link="DOF1"/>
    <origin xyz= "0 0 0.16740000128"/>
    <axis xyz= "0 0 1"/>
  </joint>

<link name="Arm_box1">
    <visual>
      <origin xyz= "0 0 0.00"/>
      <geometry>
       <box size="0.1 0.1 0.05"/>
      </geometry>
      <material name="blue"/>
    </visual>
    <collision>
      <origin xyz= "0 0 0.00"/>
      <geometry>
         <box size="0.1 0.1 0.05"/>
      </geometry>
    </collision>
  </link>

  <joint name="joint_to_Arm_box1" type="fixed">
    <parent link="DOF1"/>
    <child link="Arm_box1"/>
    <origin xyz= "0 0 0.05"/>
    <axis xyz= "0 0 1"/>
  </joint>

<link name="Arm1">
    <visual>
      <origin xyz= "0.1925 0 0"/>
      <geometry>
       <box size="0.365 0.02 0.02"/>
      </geometry>
      <material name="blue"/>
    </visual>
    <collision>
      <origin xyz= "0.1925 0 0"/>
      <geometry>
         <box size="0.365 0.02 0.02"/>
      </geometry>
    </collision>
  </link>

  <joint name="joint_to_Arm1" type="revolute">
    <limit effort="1000.0" lower="-3" upper="0.05" velocity="0.5"/>
    <parent link="Arm_box1"/>
    <child link="Arm1"/>
    <origin xyz= "0 0 0"/>
    <axis xyz= "0 1 0"/>
  </joint>

<link name="Arm_box2">
    <visual>
      <origin xyz= "0 0 0"/>
      <geometry>
       <box size="0.1 0.1 0.05"/>
      </geometry>
      <material name="blue"/>
    </visual>
    <collision>
      <origin xyz= "0 0 0"/>
      <geometry>
         <box size="0.1 0.1 0.05"/>
      </geometry>
    </collision>
  </link>

  <joint name="joint_to_Arm_box2" type="fixed">
    <parent link="Arm1"/>
    <child link="Arm_box2"/>
    <origin xyz= "0.325 0 -0.035"/>
  </joint>

<link name="Arm2">
    <visual>
      <origin xyz= "0.1925 0 0"/>
      <geometry>
       <box size="0.365 0.02 0.02"/>
      </geometry>
      <material name="blue"/>
    </visual>
    <collision>
      <origin xyz= "0.1925 0 0"/>
      <geometry>
         <box size="0.365 0.02 0.02"/>
      </geometry>
    </collision>
  </link>

  <joint name="joint_to_Arm2" type="revolute">
    <limit effort="1000.0" lower="-2.25" upper="3" velocity="0.5"/>
    <parent link="Arm_box2"/>
    <child link="Arm2"/>
    <origin xyz= "0 0 0"/>
    <axis xyz= "0 1 0"/>
  </joint>

<link name="Arm_box3">
    <visual>
      <origin xyz= "0 0 0"/>
      <geometry>
       <box size="0.1 0.1 0.05"/>
      </geometry>
      <material name="blue"/>
    </visual>
    <collision>
      <origin xyz= "0 0 0"/>
      <geometry>
         <box size="0.1 0.1 0.05"/>
      </geometry>
    </collision>
  </link>

  <joint name="joint_to_Arm_box3" type="fixed">
    <parent link="Arm2"/>
    <child link="Arm_box3"/>
    <origin xyz= "0.325 0 0.035"/>
  </joint>

<link name="Arm3">
    <visual>
      <origin xyz= "0.1925 0 0"/>
      <geometry>
       <box size="0.365 0.02 0.02"/>
      </geometry>
      <material name="blue"/>
    </visual>
    <collision>
      <origin xyz= "0.1925 0 0"/>
      <geometry>
        <box size="0.365 0.02 0.02"/>
      </geometry>
    </collision>
  </link>

  <joint name="joint_to_Arm3" type="revolute">
    <limit effort="1000.0" lower="-2.6" upper="2.25" velocity="0.5"/>
    <parent link="Arm_box3"/>
    <child link="Arm3"/>
    <origin xyz= "0 0 0"/>
    <axis xyz= "0 1 0"/>
  </joint>

  <gazebo reference="Robot_arm">
   <material>Gazebo/Blue</material>
  </gazebo>
</robot>
